<?xml version="1.0"?>
<sdf version="1.9">
  <model name="sirius_robot">
    <pose>0 0 0.12 0 0 0</pose>

    <!-- Base Link -->
    <link name="base_link">
      <pose>0 0 0 0 0 0</pose>
      <inertial>
        <mass>2.0</mass>
        <inertia>
          <ixx>0.05</ixx>
          <ixy>0</ixy>
          <ixz>0</ixz>
          <iyy>0.08</iyy>
          <iyz>0</iyz>
          <izz>0.08</izz>
        </inertia>
      </inertial>
      <visual name="base_visual">
        <geometry>
          <box>
            <size>0.6 0.4 0.15</size>
          </box>
        </geometry>
        <material>
          <ambient>0.1 0.3 0.8 1</ambient>
          <diffuse>0.1 0.3 0.8 1</diffuse>
          <specular>0.1 0.1 0.1 1</specular>
        </material>
      </visual>
      <collision name="base_collision">
        <geometry>
          <box>
            <size>0.6 0.4 0.15</size>
          </box>
        </geometry>
      </collision>
    </link>

    <!-- Left Wheel -->
    <link name="left_wheel">
      <pose>0 0.2 -0.075 -1.5708 0 0</pose>
      <inertial>
        <mass>0.8</mass>
        <inertia>
          <ixx>0.0032</ixx>
          <ixy>0</ixy>
          <ixz>0</ixz>
          <iyy>0.0032</iyy>
          <iyz>0</iyz>
          <izz>0.0058</izz>
        </inertia>
      </inertial>
      <visual name="left_wheel_visual">
        <geometry>
          <cylinder>
            <radius>0.12</radius>
            <length>0.06</length>
          </cylinder>
        </geometry>
        <material>
          <ambient>0 0 0 1</ambient>
          <diffuse>0 0 0 1</diffuse>
          <specular>0.1 0.1 0.1 1</specular>
        </material>
      </visual>
      <collision name="left_wheel_collision">
        <geometry>
          <cylinder>
            <radius>0.12</radius>
            <length>0.06</length>
          </cylinder>
        </geometry>
      </collision>
    </link>

    <!-- Right Wheel -->
    <link name="right_wheel">
      <pose>0 -0.2 -0.075 -1.5708 0 0</pose>
      <inertial>
        <mass>0.8</mass>
        <inertia>
          <ixx>0.0032</ixx>
          <ixy>0</ixy>
          <ixz>0</ixz>
          <iyy>0.0032</iyy>
          <iyz>0</iyz>
          <izz>0.0058</izz>
        </inertia>
      </inertial>
      <visual name="right_wheel_visual">
        <geometry>
          <cylinder>
            <radius>0.12</radius>
            <length>0.06</length>
          </cylinder>
        </geometry>
        <material>
          <ambient>0 0 0 1</ambient>
          <diffuse>0 0 0 1</diffuse>
          <specular>0.1 0.1 0.1 1</specular>
        </material>
      </visual>
      <collision name="right_wheel_collision">
        <geometry>
          <cylinder>
            <radius>0.12</radius>
            <length>0.06</length>
          </cylinder>
        </geometry>
      </collision>
    </link>

    <!-- Front Caster -->
    <link name="front_caster">
      <pose>0.24 0 -0.135 0 0 0</pose>
      <inertial>
        <mass>0.1</mass>
        <inertia>
          <ixx>0.000144</ixx>
          <ixy>0</ixy>
          <ixz>0</ixz>
          <iyy>0.000144</iyy>
          <iyz>0</iyz>
          <izz>0.000144</izz>
        </inertia>
      </inertial>
      <visual name="front_caster_visual">
        <geometry>
          <sphere>
            <radius>0.06</radius>
          </sphere>
        </geometry>
        <material>
          <ambient>0.8 0.8 0.8 1</ambient>
          <diffuse>0.8 0.8 0.8 1</diffuse>
          <specular>0.1 0.1 0.1 1</specular>
        </material>
      </visual>
      <collision name="front_caster_collision">
        <geometry>
          <sphere>
            <radius>0.06</radius>
          </sphere>
        </geometry>
      </collision>
    </link>

    <!-- Rear Caster -->
    <link name="rear_caster">
      <pose>-0.24 0 -0.135 0 0 0</pose>
      <inertial>
        <mass>0.1</mass>
        <inertia>
          <ixx>0.000144</ixx>
          <ixy>0</ixy>
          <ixz>0</ixz>
          <iyy>0.000144</iyy>
          <iyz>0</iyz>
          <izz>0.000144</izz>
        </inertia>
      </inertial>
      <visual name="rear_caster_visual">
        <geometry>
          <sphere>
            <radius>0.06</radius>
          </sphere>
        </geometry>
        <material>
          <ambient>0.8 0.8 0.8 1</ambient>
          <diffuse>0.8 0.8 0.8 1</diffuse>
          <specular>0.1 0.1 0.1 1</specular>
        </material>
      </visual>
      <collision name="rear_caster_collision">
        <geometry>
          <sphere>
            <radius>0.06</radius>
          </sphere>
        </geometry>
      </collision>
    </link>

    <!-- Joints -->
    <joint name="left_wheel_joint" type="revolute">
      <parent>base_link</parent>
      <child>left_wheel</child>
      <axis>
        <xyz>0 1 0</xyz>
      </axis>
    </joint>

    <joint name="right_wheel_joint" type="revolute">
      <parent>base_link</parent>
      <child>right_wheel</child>
      <axis>
        <xyz>0 1 0</xyz>
      </axis>
    </joint>

    <joint name="front_caster_joint" type="fixed">
      <parent>base_link</parent>
      <child>front_caster</child>
    </joint>

    <joint name="rear_caster_joint" type="fixed">
      <parent>base_link</parent>
      <child>rear_caster</child>
    </joint>

  </model>
</sdf>
